{"market":"0x2fb31813a2137dfcb84a4c2df8397f195b661041f53a65d8d044e20efd698ab6", "price_changes":[{"asset_id":"42094421639242820308634865598093706621873689829470528705784979409657652576818", "price":"0.13", "size":"15.15", "side":"BUY", "hash":"f7b031860d6177049aa4adfee60b216d11759939", "best_bid":"0.49", "best_ask":"0.5"}, {"asset_id":"92017110144905079791232358864642972071173412507030204253095513706486374686193", "price":"0.87", "size":"15.15", "side":"SELL", "hash":"4e9e01cb632aa0df9eed956340eb3ad14be0f8d2", "best_bid":"0.5", "best_ask":"0.51"}], "timestamp":"1782480061422", "event_type":"price_change"}
{"market":"0x2fb31813a2137dfcb84a4c2df8397f195b661041f53a65d8d044e20efd698ab6", "price_changes":[{"asset_id":"92017110144905079791232358864642972071173412507030204253095513706486374686193", "price":"0.02", "size":"837.9", "side":"BUY", "hash":"73cc19d0fdab76ea5e3c60280f4e0f9b4138d515", "best_bid":"0.5", "best_ask":"0.51"}, {"asset_id":"42094421639242820308634865598093706621873689829470528705784979409657652576818", "price":"0.98", "size":"837.9", "side":"SELL", "hash":"fcc9b0b2f20920531f2aeae69df04e347e46dbdc", "best_bid":"0.49", "best_ask":"0.5"}], "timestamp":"1782480061424", "event_type":"price_change"}
{"market":"0x2fb31813a2137dfcb84a4c2df8397f195b661041f53a65d8d044e20efd698ab6", "price_changes":[{"asset_id":"42094421639242820308634865598093706621873689829470528705784979409657652576818", "price":"0.02", "size":"837.98", "side":"BUY", "hash":"b9013ed2431c51d7fa8ea0f6988a81d05bfac8e3", "best_bid":"0.49", "best_ask":"0.5"}, {"asset_id":"92017110144905079791232358864642972071173412507030204253095513706486374686193", "price":"0.98", "size":"837.98", "side":"SELL", "hash":"8d07c5887e8b61da87743da97ebab615e5a1e7c4", "best_bid":"0.5", "best_ask":"0.51"}], "timestamp":"1782480061426", "event_type":"price_change"}
{"market":"0x2fb31813a2137dfcb84a4c2df8397f195b661041f53a65d8d044e20efd698ab6", "price_changes":[{"asset_id":"92017110144905079791232358864642972071173412507030204253095513706486374686193", "price":"0.05", "size":"571.82", "side":"BUY", "hash":"33454e061c2bf4fc5138377c9df0e1bd51aecc9c", "best_bid":"0.5", "best_ask":"0.51"}, {"asset_id":"42094421639242820308634865598093706621873689829470528705784979409657652576818", "price":"0.95", "size":"571.82", "side":"SELL", "hash":"ce150922ef3fa012bab5a5132f886b4b65eb00d3", "best_bid":"0.49", "best_ask":"0.5"}], "timestamp":"1782480061430", "event_type":"price_change"}
{"market":"0x2fb31813a2137dfcb84a4c2df8397f195b661041f53a65d8d044e20efd698ab6", "price_changes":[{"asset_id":"42094421639242820308634865598093706621873689829470528705784979409657652576818", "price":"0.01", "size":"7444.49", "side":"BUY", "hash":"918823f5e429788467eebf8d4e2dbfeba8676bb4", "best_bid":"0.49", "best_ask":"0.5"}, {"asset_id":"92017110144905079791232358864642972071173412507030204253095513706486374686193", "price":"0.99", "size":"7444.49", "side":"SELL", "hash":"011dc0e67e62edcf57ffd44ad650ca604b19db2b", "best_bid":"0.5", "best_ask":"0.51"}], "timestamp":"1782480061431", "event_type":"price_change"}
{"market":"0x2fb31813a2137dfcb84a4c2df8397f195b661041f53a65d8d044e20efd698ab6", "price_changes":[{"asset_id":"92017110144905079791232358864642972071173412507030204253095513706486374686193", "price":"0.13", "size":"15.2", "side":"BUY", "hash":"3c5fdd99c17083422394e54ff3b1189572353e10", "best_bid":"0.5", "best_ask":"0.51"}, {"asset_id":"42094421639242820308634865598093706621873689829470528705784979409657652576818", "price":"0.87", "size":"15.2", "side":"SELL", "hash":"283973e85ef31947ee805d02a22d41466f29d3eb", "best_bid":"0.49", "best_ask":"0.5"}], "timestamp":"1782480061438", "event_type":"price_change"}
{"market":"0x2fb31813a2137dfcb84a4c2df8397f195b661041f53a65d8d044e20efd698ab6", "price_changes":[{"asset_id":"42094421639242820308634865598093706621873689829470528705784979409657652576818", "price":"0.05", "size":"571.91", "side":"BUY", "hash":"c5d3b26940d0997a0a123f6f08ba1b5c16e14f52", "best_bid":"0.49", "best_ask":"0.5"}, {"asset_id":"92017110144905079791232358864642972071173412507030204253095513706486374686193", "price":"0.95", "size":"571.91", "side":"SELL", "hash":"18fee0081a2bf00bec46c7ed9e881c8865bb8b27", "best_bid":"0.5", "best_ask":"0.51"}], "timestamp":"1782480061441", "event_type":"price_change"}
{"market":"0x2fb31813a2137dfcb84a4c2df8397f195b661041f53a65d8d044e20efd698ab6", "price_changes":[{"asset_id":"92017110144905079791232358864642972071173412507030204253095513706486374686193", "price":"0.01", "size":"7444.46", "side":"BUY", "hash":"1058b649f2b52fa266c27bbb6edcaa0606247d7e", "best_bid":"0.5", "best_ask":"0.51"}, {"asset_id":"42094421639242820308634865598093706621873689829470528705784979409657652576818", "price":"0.99", "size":"7444.46", "side":"SELL", "hash":"8198a30189af1a952f33700561d5aa87dcfd95ee", "best_bid":"0.49", "best_ask":"0.5"}], "timestamp":"1782480061443", "event_type":"price_change"}
{"market":"0x2fb31813a2137dfcb84a4c2df8397f195b661041f53a65d8d044e20efd698ab6", "price_changes":[{"asset_id":"92017110144905079791232358864642972071173412507030204253095513706486374686193", "price":"0.03", "size":"5737", "side":"BUY", "hash":"73f91232ead311565b0a74102b04c059d81005d8", "best_bid":"0.5", "best_ask":"0.51"}, {"asset_id":"42094421639242820308634865598093706621873689829470528705784979409657652576818", "price":"0.97", "size":"5737", "side":"SELL", "hash":"a50a178763fce5cff6b762e67e8c22eddb5d8b50", "best_bid":"0.49", "best_ask":"0.5"}], "timestamp":"1782480161903", "event_type":"price_change"}
{"market":"0x2fb31813a2137dfcb84a4c2df8397f195b661041f53a65d8d044e20efd698ab6", "price_changes":[{"asset_id":"42094421639242820308634865598093706621873689829470528705784979409657652576818", "price":"0.03", "size":"5737", "side":"BUY", "hash":"c800243e40532c8a3d01ca64482532fdbc5d5244", "best_bid":"0.49", "best_ask":"0.5"}, {"asset_id":"92017110144905079791232358864642972071173412507030204253095513706486374686193", "price":"0.97", "size":"5737", "side":"SELL", "hash":"66c4f7ced268ad6758d38e59258e7870cf74580c", "best_bid":"0.5", "best_ask":"0.51"}], "timestamp":"1782480162025", "event_type":"price_change"}
{"market":"0x2fb31813a2137dfcb84a4c2df8397f195b661041f53a65d8d044e20efd698ab6", "price_changes":[{"asset_id":"92017110144905079791232358864642972071173412507030204253095513706486374686193", "price":"0.5", "size":"3", "side":"BUY", "hash":"67abd713db6636f6129870ea8a92494a0d6e1edd", "best_bid":"0.5", "best_ask":"0.51"}, {"asset_id":"42094421639242820308634865598093706621873689829470528705784979409657652576818", "price":"0.5", "size":"3", "side":"SELL", "hash":"842eef1adf4e6bbc648591667026e2c76574d631", "best_bid":"0.49", "best_ask":"0.5"}], "timestamp":"1782480232071", "event_type":"price_change"}
{"market":"0x2fb31813a2137dfcb84a4c2df8397f195b661041f53a65d8d044e20efd698ab6", "price_changes":[{"asset_id":"92017110144905079791232358864642972071173412507030204253095513706486374686193", "price":"0.01", "size":"7394.46", "side":"BUY", "hash":"c0d7dff2d62d57301d5f6af9700c186bfcb51d25", "best_bid":"0.5", "best_ask":"0.51"}, {"asset_id":"42094421639242820308634865598093706621873689829470528705784979409657652576818", "price":"0.99", "size":"7394.46", "side":"SELL", "hash":"ecfb70b03927925623c9cdd75a8041d5fc5d4f77", "best_bid":"0.49", "best_ask":"0.5"}], "timestamp":"1782480333689", "event_type":"price_change"}
{"market":"0x2fb31813a2137dfcb84a4c2df8397f195b661041f53a65d8d044e20efd698ab6", "price_changes":[{"asset_id":"42094421639242820308634865598093706621873689829470528705784979409657652576818", "price":"0.01", "size":"7394.49", "side":"BUY", "hash":"54db0f171f2d9c747bc304126a973979d8e0c314", "best_bid":"0.49", "best_ask":"0.5"}, {"asset_id":"92017110144905079791232358864642972071173412507030204253095513706486374686193", "price":"0.99", "size":"7394.49", "side":"SELL", "hash":"846273ec1bd51d0b125d1297a13aa3c69ed80f6e", "best_bid":"0.5", "best_ask":"0.51"}], "timestamp":"1782480333739", "event_type":"price_change"}
{"market":"0xcee5705c67c9d0468a50aaad6b7ae775c09c2ba7cc85dc1f38e70e4702eea118", "price_changes":[{"asset_id":"16200719422208844254054192274740319849202112652733334412062025960793588929636", "price":"0.02", "size":"50", "side":"BUY", "hash":"afd01e100bab9adb7246b69dd8a39219445420dc", "best_bid":"0.02", "best_ask":"1"}, {"asset_id":"75250261688638828906810019218938209379966777943905437964965307502226911711176", "price":"0.98", "size":"50", "side":"SELL", "hash":"12ddab88c14fbd30d5744ac9bfedc57d7089e032", "best_bid":"0", "best_ask":"0.98"}], "timestamp":"1782480761955", "event_type":"price_change"}
{"market":"0xcee5705c67c9d0468a50aaad6b7ae775c09c2ba7cc85dc1f38e70e4702eea118", "price_changes":[{"asset_id":"75250261688638828906810019218938209379966777943905437964965307502226911711176", "price":"0.02", "size":"50", "side":"BUY", "hash":"6370e36711845fc063ed4551e2425525a6ad6315", "best_bid":"0.02", "best_ask":"0.98"}, {"asset_id":"16200719422208844254054192274740319849202112652733334412062025960793588929636", "price":"0.98", "size":"50", "side":"SELL", "hash":"1e5559a4698487502633bcab8bd99db762fa7ce9", "best_bid":"0.02", "best_ask":"0.98"}], "timestamp":"1782480762081", "event_type":"price_change"}
{"market":"0x36102c1131cb664d8cfd4ed18a50654294114322fc2fe4b59c8c9ca65306bed4", "price_changes":[{"asset_id":"82532866353244417984784855062829867486030113407108719332201252828896164585537", "price":"0.01", "size":"473", "side":"BUY", "hash":"c44f9bc6a89c6bc74ea03f41eaedc7b6ace84e8b", "best_bid":"0.02", "best_ask":"0.99"}, {"asset_id":"29481742380475145027768198040671447403410107408341340950447614951266747549536", "price":"0.99", "size":"473", "side":"SELL", "hash":"0323ab10682faeb18773f06b78f2e46a110b9c76", "best_bid":"0.01", "best_ask":"0.98"}], "timestamp":"1782480762824", "event_type":"price_change"}
{"market":"0x36102c1131cb664d8cfd4ed18a50654294114322fc2fe4b59c8c9ca65306bed4", "price_changes":[{"asset_id":"82532866353244417984784855062829867486030113407108719332201252828896164585537", "price":"0.02", "size":"75", "side":"BUY", "hash":"323aae55530717a13bdccda59145fdd328e5b2e8", "best_bid":"0.02", "best_ask":"0.99"}, {"asset_id":"29481742380475145027768198040671447403410107408341340950447614951266747549536", "price":"0.98", "size":"75", "side":"SELL", "hash":"fcc09bac71f2729ce4293b915f2785634f839c20", "best_bid":"0.01", "best_ask":"0.98"}], "timestamp":"1782480762825", "event_type":"price_change"}
{"market":"0x36102c1131cb664d8cfd4ed18a50654294114322fc2fe4b59c8c9ca65306bed4", "price_changes":[{"asset_id":"82532866353244417984784855062829867486030113407108719332201252828896164585537", "price":"0.01", "size":"482", "side":"BUY", "hash":"d43d3480ebf80ce4054227e517e4a0539f3ea8ba", "best_bid":"0.02", "best_ask":"0.99"}, {"asset_id":"29481742380475145027768198040671447403410107408341340950447614951266747549536", "price":"0.99", "size":"482", "side":"SELL", "hash":"1396d6ec5fb15923b259b4d917030b7a9ee3d282", "best_bid":"0.01", "best_ask":"0.98"}], "timestamp":"1782480762826", "event_type":"price_change"}
{"market":"0x36102c1131cb664d8cfd4ed18a50654294114322fc2fe4b59c8c9ca65306bed4", "price_changes":[{"asset_id":"82532866353244417984784855062829867486030113407108719332201252828896164585537", "price":"0.01", "size":"491", "side":"BUY", "hash":"05d1ec2822080e81453ff3815b0444bcfbdc98d2", "best_bid":"0.02", "best_ask":"0.99"}, {"asset_id":"29481742380475145027768198040671447403410107408341340950447614951266747549536", "price":"0.99", "size":"491", "side":"SELL", "hash":"67e5ec52f087f050cfc954ec738d1d00e9e9fbc9", "best_bid":"0.01", "best_ask":"0.98"}], "timestamp":"1782480762829", "event_type":"price_change"}
{"market":"0x36102c1131cb664d8cfd4ed18a50654294114322fc2fe4b59c8c9ca65306bed4", "price_changes":[{"asset_id":"29481742380475145027768198040671447403410107408341340950447614951266747549536", "price":"0.02", "size":"25", "side":"BUY", "hash":"f3c8e51365ec3a6b001d880baed5ff560d02d6a1", "best_bid":"0.02", "best_ask":"0.98"}, {"asset_id":"82532866353244417984784855062829867486030113407108719332201252828896164585537", "price":"0.98", "size":"25", "side":"SELL", "hash":"8fbac3488f63f8867da9485631e1c38d52539215", "best_bid":"0.02", "best_ask":"0.98"}], "timestamp":"1782480762830", "event_type":"price_change"}
{"market":"0x36102c1131cb664d8cfd4ed18a50654294114322fc2fe4b59c8c9ca65306bed4", "price_changes":[{"asset_id":"29481742380475145027768198040671447403410107408341340950447614951266747549536", "price":"0.01", "size":"455", "side":"BUY", "hash":"654a925b77629236cd0f3e595e8d5adcd47913cc", "best_bid":"0.02", "best_ask":"0.98"}, {"asset_id":"82532866353244417984784855062829867486030113407108719332201252828896164585537", "price":"0.99", "size":"455", "side":"SELL", "hash":"31d664975ffdad3113e856f3a90bf96fed0046dc", "best_bid":"0.02", "best_ask":"0.98"}], "timestamp":"1782480762833", "event_type":"price_change"}
{"market":"0x36102c1131cb664d8cfd4ed18a50654294114322fc2fe4b59c8c9ca65306bed4", "price_changes":[{"asset_id":"82532866353244417984784855062829867486030113407108719332201252828896164585537", "price":"0.03", "size":"10", "side":"BUY", "hash":"5e9c4e51957d463cc4a9774f5ccdbe9888333017", "best_bid":"0.03", "best_ask":"0.98"}, {"asset_id":"29481742380475145027768198040671447403410107408341340950447614951266747549536", "price":"0.97", "size":"10", "side":"SELL", "hash":"b40a9685e5ed9e7c182f862eafebc722c8712efd", "best_bid":"0.02", "best_ask":"0.97"}], "timestamp":"1782480762837", "event_type":"price_change"}
{"market":"0x36102c1131cb664d8cfd4ed18a50654294114322fc2fe4b59c8c9ca65306bed4", "price_changes":[{"asset_id":"29481742380475145027768198040671447403410107408341340950447614951266747549536", "price":"0.01", "size":"464", "side":"BUY", "hash":"8588b0df53a76266a7d95b7113325790f457e7ef", "best_bid":"0.02", "best_ask":"0.97"}, {"asset_id":"82532866353244417984784855062829867486030113407108719332201252828896164585537", "price":"0.99", "size":"464", "side":"SELL", "hash":"845945434851b86c49896dbbb7ac3297a27eba84", "best_bid":"0.03", "best_ask":"0.98"}], "timestamp":"1782480762838", "event_type":"price_change"}
{"market":"0x36102c1131cb664d8cfd4ed18a50654294114322fc2fe4b59c8c9ca65306bed4", "price_changes":[{"asset_id":"29481742380475145027768198040671447403410107408341340950447614951266747549536", "price":"0.11", "size":"10", "side":"BUY", "hash":"dd784c8865842347a2049f5f314d91a095a6d1e6", "best_bid":"0.11", "best_ask":"0.97"}, {"asset_id":"82532866353244417984784855062829867486030113407108719332201252828896164585537", "price":"0.89", "size":"10", "side":"SELL", "hash":"7122e67119a9efc587bb7474f02fbc31e02274c1", "best_bid":"0.03", "best_ask":"0.89"}], "timestamp":"1782480762839", "event_type":"price_change"}
{"market":"0x36102c1131cb664d8cfd4ed18a50654294114322fc2fe4b59c8c9ca65306bed4", "price_changes":[{"asset_id":"82532866353244417984784855062829867486030113407108719332201252828896164585537", "price":"0.49", "size":"10", "side":"BUY", "hash":"ef87726cbf8df952216f6c98cbd621d27e8ec126", "best_bid":"0.49", "best_ask":"0.89"}, {"asset_id":"29481742380475145027768198040671447403410107408341340950447614951266747549536", "price":"0.51", "size":"10", "side":"SELL", "hash":"2c69f93522112a760e2303c3f593b4a25ba3ba77", "best_bid":"0.11", "best_ask":"0.51"}], "timestamp":"1782480762844", "event_type":"price_change"}
{"market":"0x36102c1131cb664d8cfd4ed18a50654294114322fc2fe4b59c8c9ca65306bed4", "price_changes":[{"asset_id":"29481742380475145027768198040671447403410107408341340950447614951266747549536", "price":"0.09", "size":"10", "side":"BUY", "hash":"f8980ae894a5ca9b4a3473e014fc9c9f66e79b66", "best_bid":"0.11", "best_ask":"0.51"}, {"asset_id":"82532866353244417984784855062829867486030113407108719332201252828896164585537", "price":"0.91", "size":"10", "side":"SELL", "hash":"2664d52ad4cc00a688722abbd8ab5e7bfdc1467a", "best_bid":"0.49", "best_ask":"0.89"}], "timestamp":"1782480762845", "event_type":"price_change"}
{"market":"0x36102c1131cb664d8cfd4ed18a50654294114322fc2fe4b59c8c9ca65306bed4", "price_changes":[{"asset_id":"82532866353244417984784855062829867486030113407108719332201252828896164585537", "price":"0.02", "size":"100", "side":"BUY", "hash":"7be71d54688bf0147723e799a46fe6086672a3ec", "best_bid":"0.49", "best_ask":"0.89"}, {"asset_id":"29481742380475145027768198040671447403410107408341340950447614951266747549536", "price":"0.98", "size":"100", "side":"SELL", "hash":"e07def45725dca5dec5ef054d9db6474520bf362", "best_bid":"0.11", "best_ask":"0.51"}], "timestamp":"1782480762846", "event_type":"price_change"}
{"market":"0x36102c1131cb664d8cfd4ed18a50654294114322fc2fe4b59c8c9ca65306bed4", "price_changes":[{"asset_id":"29481742380475145027768198040671447403410107408341340950447614951266747549536", "price":"0.01", "size":"473", "side":"BUY", "hash":"eae5b90fc88785615808f5f9b3099ea3fd37b4a6", "best_bid":"0.11", "best_ask":"0.51"}, {"asset_id":"82532866353244417984784855062829867486030113407108719332201252828896164585537", "price":"0.99", "size":"473", "side":"SELL", "hash":"88e4d6e5e91e883142bc0de3400d399207b221f0", "best_bid":"0.49", "best_ask":"0.89"}], "timestamp":"1782480762847", "event_type":"price_change"}
{"market":"0x36102c1131cb664d8cfd4ed18a50654294114322fc2fe4b59c8c9ca65306bed4", "price_changes":[{"asset_id":"29481742380475145027768198040671447403410107408341340950447614951266747549536", "price":"0.49", "size":"10", "side":"BUY", "hash":"a56e165bfc917c491f7e0c7774c377a4a686e6ef", "best_bid":"0.49", "best_ask":"0.51"}, {"asset_id":"82532866353244417984784855062829867486030113407108719332201252828896164585537", "price":"0.51", "size":"10", "side":"SELL", "hash":"c8e6bc2fa77cc89ccb444dcf862b75e29d022b5d", "best_bid":"0.49", "best_ask":"0.51"}], "timestamp":"1782480762848", "event_type":"price_change"}
{"market":"0x36102c1131cb664d8cfd4ed18a50654294114322fc2fe4b59c8c9ca65306bed4", "price_changes":[{"asset_id":"29481742380475145027768198040671447403410107408341340950447614951266747549536", "price":"0.02", "size":"50", "side":"BUY", "hash":"f15fde2190324065612d55a4a9bdba5e5d7ac93c", "best_bid":"0.49", "best_ask":"0.51"}, {"asset_id":"82532866353244417984784855062829867486030113407108719332201252828896164585537", "price":"0.98", "size":"50", "side":"SELL", "hash":"16bf93d86101031768bbae3db93eadbc2c54cca8", "best_bid":"0.49", "best_ask":"0.51"}], "timestamp":"1782480762849", "event_type":"price_change"}
{"market":"0x36102c1131cb664d8cfd4ed18a50654294114322fc2fe4b59c8c9ca65306bed4", "price_changes":[{"asset_id":"29481742380475145027768198040671447403410107408341340950447614951266747549536", "price":"0.38", "size":"10", "side":"BUY", "hash":"2aecbc84b4805ef121ba0505cc4bf53ff4801fce", "best_bid":"0.49", "best_ask":"0.51"}, {"asset_id":"82532866353244417984784855062829867486030113407108719332201252828896164585537", "price":"0.62", "size":"10", "side":"SELL", "hash":"a6413f68e5406b812e8d81316702a6484f32a947", "best_bid":"0.49", "best_ask":"0.51"}], "timestamp":"1782480762850", "event_type":"price_change"}
{"market":"0x36102c1131cb664d8cfd4ed18a50654294114322fc2fe4b59c8c9ca65306bed4", "price_changes":[{"asset_id":"29481742380475145027768198040671447403410107408341340950447614951266747549536", "price":"0.02", "size":"75", "side":"BUY", "hash":"ee4bb27c4e44b5b6c2d6edf32a59763b296263a2", "best_bid":"0.49", "best_ask":"0.51"}, {"asset_id":"82532866353244417984784855062829867486030113407108719332201252828896164585537", "price":"0.98", "size":"75", "side":"SELL", "hash":"f5b47c1b1a1bf0431c15aced834680ab121991c2", "best_bid":"0.49", "best_ask":"0.51"}], "timestamp":"1782480762851", "event_type":"price_change"}
{"market":"0x36102c1131cb664d8cfd4ed18a50654294114322fc2fe4b59c8c9ca65306bed4", "price_changes":[{"asset_id":"82532866353244417984784855062829867486030113407108719332201252828896164585537", "price":"0.01", "size":"500", "side":"BUY", "hash":"aa2fcb27f19fa7e108b6ad4e45f83f96892d2f3c", "best_bid":"0.49", "best_ask":"0.51"}, {"asset_id":"29481742380475145027768198040671447403410107408341340950447614951266747549536", "price":"0.99", "size":"500", "side":"SELL", "hash":"008e47c79250a0cc03a23898147158870b8392f7", "best_bid":"0.49", "best_ask":"0.51"}], "timestamp":"1782480762851", "event_type":"price_change"}
{"market":"0x36102c1131cb664d8cfd4ed18a50654294114322fc2fe4b59c8c9ca65306bed4", "price_changes":[{"asset_id":"29481742380475145027768198040671447403410107408341340950447614951266747549536", "price":"0.01", "size":"482", "side":"BUY", "hash":"c23ac3c5b9ecc0f900239999f435e15c4e39f2c4", "best_bid":"0.49", "best_ask":"0.51"}, {"asset_id":"82532866353244417984784855062829867486030113407108719332201252828896164585537", "price":"0.99", "size":"482", "side":"SELL", "hash":"7717c3137023128e47129e788b6b6c4b78079e69", "best_bid":"0.49", "best_ask":"0.51"}], "timestamp":"1782480762853", "event_type":"price_change"}
{"market":"0x36102c1131cb664d8cfd4ed18a50654294114322fc2fe4b59c8c9ca65306bed4", "price_changes":[{"asset_id":"82532866353244417984784855062829867486030113407108719332201252828896164585537", "price":"0.16", "size":"10", "side":"BUY", "hash":"b64940ba8935aa2c9488aa9ac13ab2b77403748d", "best_bid":"0.49", "best_ask":"0.51"}, {"asset_id":"29481742380475145027768198040671447403410107408341340950447614951266747549536", "price":"0.84", "size":"10", "side":"SELL", "hash":"4821ad30b8335b1781c74cc022fe384e01837d7f", "best_bid":"0.49", "best_ask":"0.51"}], "timestamp":"1782480762854", "event_type":"price_change"}
{"market":"0x36102c1131cb664d8cfd4ed18a50654294114322fc2fe4b59c8c9ca65306bed4", "price_changes":[{"asset_id":"29481742380475145027768198040671447403410107408341340950447614951266747549536", "price":"0.01", "size":"532", "side":"BUY", "hash":"e5239081592ff54680187002c0c795e864ac28fc", "best_bid":"0.49", "best_ask":"0.51"}, {"asset_id":"82532866353244417984784855062829867486030113407108719332201252828896164585537", "price":"0.99", "size":"532", "side":"SELL", "hash":"d422890040b3a00c1f625e197e78298b5529f451", "best_bid":"0.49", "best_ask":"0.51"}], "timestamp":"1782480762855", "event_type":"price_change"}
{"market":"0x36102c1131cb664d8cfd4ed18a50654294114322fc2fe4b59c8c9ca65306bed4", "price_changes":[{"asset_id":"29481742380475145027768198040671447403410107408341340950447614951266747549536", "price":"0.02", "size":"100", "side":"BUY", "hash":"04b380e9f60cf29cd9ee37ade82abcd2f7ec8d3f", "best_bid":"0.49", "best_ask":"0.51"}, {"asset_id":"82532866353244417984784855062829867486030113407108719332201252828896164585537", "price":"0.98", "size":"100", "side":"SELL", "hash":"76e38465c47de8d6ea7be2a6f6e4a8be84866b56", "best_bid":"0.49", "best_ask":"0.51"}], "timestamp":"1782480762863", "event_type":"price_change"}
{"market":"0x36102c1131cb664d8cfd4ed18a50654294114322fc2fe4b59c8c9ca65306bed4", "price_changes":[{"asset_id":"82532866353244417984784855062829867486030113407108719332201252828896164585537", "price":"0.01", "size":"509", "side":"BUY", "hash":"3295f0356b0641c00a47c0881b67fb664ff66efe", "best_bid":"0.49", "best_ask":"0.51"}, {"asset_id":"29481742380475145027768198040671447403410107408341340950447614951266747549536", "price":"0.99", "size":"509", "side":"SELL", "hash":"c6ac245b111461e7587ba4afc418f0fdc4175102", "best_bid":"0.49", "best_ask":"0.51"}], "timestamp":"1782480762864", "event_type":"price_change"}
{"market":"0x36102c1131cb664d8cfd4ed18a50654294114322fc2fe4b59c8c9ca65306bed4", "price_changes":[{"asset_id":"29481742380475145027768198040671447403410107408341340950447614951266747549536", "price":"0.03", "size":"3000", "side":"BUY", "hash":"1edd6bd57f307ac59686a418793723d413dffbd1", "best_bid":"0.49", "best_ask":"0.51"}, {"asset_id":"82532866353244417984784855062829867486030113407108719332201252828896164585537", "price":"0.97", "size":"3000", "side":"SELL", "hash":"7a24583c1e78de58bd8eedff7c41a3e7cccb54c3", "best_bid":"0.49", "best_ask":"0.51"}], "timestamp":"1782480762865", "event_type":"price_change"}
{"market":"0x36102c1131cb664d8cfd4ed18a50654294114322fc2fe4b59c8c9ca65306bed4", "price_changes":[{"asset_id":"29481742380475145027768198040671447403410107408341340950447614951266747549536", "price":"0.07", "size":"10", "side":"BUY", "hash":"14a34284f1ca46f8cac4228f5325ebbc3616a44d", "best_bid":"0.49", "best_ask":"0.51"}, {"asset_id":"82532866353244417984784855062829867486030113407108719332201252828896164585537", "price":"0.93", "size":"10", "side":"SELL", "hash":"f112900cbb910528b46e1cf4af437ff538b442b1", "best_bid":"0.49", "best_ask":"0.51"}], "timestamp":"1782480762866", "event_type":"price_change"}
{"market":"0x36102c1131cb664d8cfd4ed18a50654294114322fc2fe4b59c8c9ca65306bed4", "price_changes":[{"asset_id":"29481742380475145027768198040671447403410107408341340950447614951266747549536", "price":"0.49", "size":"27", "side":"BUY", "hash":"b49fb54946c2ec025d3309b3f1f63ddbca25481c", "best_bid":"0.49", "best_ask":"0.51"}, {"asset_id":"82532866353244417984784855062829867486030113407108719332201252828896164585537", "price":"0.51", "size":"27", "side":"SELL", "hash":"f3686867d962b544b527620ed84e5d4bd1829a71", "best_bid":"0.49", "best_ask":"0.51"}], "timestamp":"1782480762867", "event_type":"price_change"}
{"market":"0x36102c1131cb664d8cfd4ed18a50654294114322fc2fe4b59c8c9ca65306bed4", "price_changes":[{"asset_id":"82532866353244417984784855062829867486030113407108719332201252828896164585537", "price":"0.01", "size":"559", "side":"BUY", "hash":"be122acdf537a076bb68485dbf9a64b326d01abe", "best_bid":"0.49", "best_ask":"0.51"}, {"asset_id":"29481742380475145027768198040671447403410107408341340950447614951266747549536", "price":"0.99", "size":"559", "side":"SELL", "hash":"f710a3f06ca9afb00152410ba277f0d7a8036dd2", "best_bid":"0.49", "best_ask":"0.51"}], "timestamp":"1782480762868", "event_type":"price_change"}
{"market":"0x36102c1131cb664d8cfd4ed18a50654294114322fc2fe4b59c8c9ca65306bed4", "price_changes":[{"asset_id":"29481742380475145027768198040671447403410107408341340950447614951266747549536", "price":"0.02", "size":"125", "side":"BUY", "hash":"b14f152d1fad383d52ecc6e8292b58f83f13e272", "best_bid":"0.49", "best_ask":"0.51"}, {"asset_id":"82532866353244417984784855062829867486030113407108719332201252828896164585537", "price":"0.98", "size":"125", "side":"SELL", "hash":"bbb96c52de8f6412708d54233a96a66e37aa63bc", "best_bid":"0.49", "best_ask":"0.51"}], "timestamp":"1782480762869", "event_type":"price_change"}
{"market":"0x36102c1131cb664d8cfd4ed18a50654294114322fc2fe4b59c8c9ca65306bed4", "price_changes":[{"asset_id":"82532866353244417984784855062829867486030113407108719332201252828896164585537", "price":"0.03", "size":"3010", "side":"BUY", "hash":"e81f2c6a66eb585b8cf13f989d143a4ed10ac645", "best_bid":"0.49", "best_ask":"0.51"}, {"asset_id":"29481742380475145027768198040671447403410107408341340950447614951266747549536", "price":"0.97", "size":"3010", "side":"SELL", "hash":"f594783aad5608585b050d0fef46c2e160fb0d40", "best_bid":"0.49", "best_ask":"0.51"}], "timestamp":"1782480762870", "event_type":"price_change"}
{"market":"0x36102c1131cb664d8cfd4ed18a50654294114322fc2fe4b59c8c9ca65306bed4", "price_changes":[{"asset_id":"29481742380475145027768198040671447403410107408341340950447614951266747549536", "price":"0.01", "size":"541", "side":"BUY", "hash":"956012e8f070d568da2b2f522f1a33810d371710", "best_bid":"0.49", "best_ask":"0.51"}, {"asset_id":"82532866353244417984784855062829867486030113407108719332201252828896164585537", "price":"0.99", "size":"541", "side":"SELL", "hash":"2fbc3e37d3ed6d54740e587df2d14f525bec2cac", "best_bid":"0.49", "best_ask":"0.51"}], "timestamp":"1782480762871", "event_type":"price_change"}
{"market":"0x36102c1131cb664d8cfd4ed18a50654294114322fc2fe4b59c8c9ca65306bed4", "price_changes":[{"asset_id":"82532866353244417984784855062829867486030113407108719332201252828896164585537", "price":"0.49", "size":"27", "side":"BUY", "hash":"cbe1e0830525d1c76c604722efab4d13b5a2d09e", "best_bid":"0.49", "best_ask":"0.51"}, {"asset_id":"29481742380475145027768198040671447403410107408341340950447614951266747549536", "price":"0.51", "size":"27", "side":"SELL", "hash":"e854629e36da659e3b56fd3b7a985bec01293c51", "best_bid":"0.49", "best_ask":"0.51"}], "timestamp":"1782480762871", "event_type":"price_change"}
{"market":"0x36102c1131cb664d8cfd4ed18a50654294114322fc2fe4b59c8c9ca65306bed4", "price_changes":[{"asset_id":"82532866353244417984784855062829867486030113407108719332201252828896164585537", "price":"0.07", "size":"10", "side":"BUY", "hash":"15663c914834dcabd391290f4d747ad83bb544ac", "best_bid":"0.49", "best_ask":"0.51"}, {"asset_id":"29481742380475145027768198040671447403410107408341340950447614951266747549536", "price":"0.93", "size":"10", "side":"SELL", "hash":"74605e05a469ef9e03e609036cccd8d9eb5f7b59", "best_bid":"0.49", "best_ask":"0.51"}], "timestamp":"1782480762874", "event_type":"price_change"}
{"market":"0x36102c1131cb664d8cfd4ed18a50654294114322fc2fe4b59c8c9ca65306bed4", "price_changes":[{"asset_id":"29481742380475145027768198040671447403410107408341340950447614951266747549536", "price":"0.02", "size":"150", "side":"BUY", "hash":"a3d8a403fc1a961e0465cf529381bba9b09b589f", "best_bid":"0.49", "best_ask":"0.51"}, {"asset_id":"82532866353244417984784855062829867486030113407108719332201252828896164585537", "price":"0.98", "size":"150", "side":"SELL", "hash":"07f243f99d495d4194d413887c25cdf0a30422d9", "best_bid":"0.49", "best_ask":"0.51"}], "timestamp":"1782480762875", "event_type":"price_change"}
{"market":"0x36102c1131cb664d8cfd4ed18a50654294114322fc2fe4b59c8c9ca65306bed4", "price_changes":[{"asset_id":"29481742380475145027768198040671447403410107408341340950447614951266747549536", "price":"0.01", "size":"550", "side":"BUY", "hash":"ade85bf5633326f83a236c74773b72dd98b7bcfd", "best_bid":"0.49", "best_ask":"0.51"}, {"asset_id":"82532866353244417984784855062829867486030113407108719332201252828896164585537", "price":"0.99", "size":"550", "side":"SELL", "hash":"c1ff7e8023f439f60f73a2fb629b085ff616e013", "best_bid":"0.49", "best_ask":"0.51"}], "timestamp":"1782480762875", "event_type":"price_change"}
{"market":"0x36102c1131cb664d8cfd4ed18a50654294114322fc2fe4b59c8c9ca65306bed4", "price_changes":[{"asset_id":"29481742380475145027768198040671447403410107408341340950447614951266747549536", "price":"0.46", "size":"10", "side":"BUY", "hash":"a7162451b7fd4ac82da4e879c6fa268993e5b378", "best_bid":"0.49", "best_ask":"0.51"}, {"asset_id":"82532866353244417984784855062829867486030113407108719332201252828896164585537", "price":"0.54", "size":"10", "side":"SELL", "hash":"34368aa9e67fd91da8cb41413d002b3f3fc97308", "best_bid":"0.49", "best_ask":"0.51"}], "timestamp":"1782480762881", "event_type":"price_change"}
